data/test_orders.csv
symbol,side,type,price,quantity
AAPL,BUY,LIMIT,150.00,100
AAPL,SELL,LIMIT,151.00,50
AAPL,BUY,MARKET,,20
AAPL,SELL,LIMIT,149.50,10
AAPL,BUY,LIMIT,150.50,60
AAPL,SELL,MARKET,,5
GOOGL,BUY,LIMIT,2800.00,10
GOOGL,SELL,LIMIT,2805.00,5
GOOGL,BUY,LIMIT,2802.50,15
